Workbook

Sheet 1500 ft
C1: Depart Taxi | D1: Hover Climb | E1: Transition Climb | F1: Depart Procedures | G1: Accelerate Climb | H1: Cruise | I1: Decelerate Descend | J1: Arrive Procedures | K1: Transition Descend | L1: Hover Descend | M1: Arrive Taxi | N1: Reserve Hover Climb | O1: Reserve Transition Climb | P1: Reserve Accelerate Climb | Q1: Reserve Cruise | R1: Reserve Decelerate Descend | S1: Reserve Transition Descend | T1: Reserve Hover Descend
A2: 30 miles | B2: Archer Midnight | C2: 0.00414 | D2: 1.410868 | E2: 2.095849 | F2: 0.548625 | G2: 3.448231 | H2: 40.956658 | I2: 0.968789 | J2: 0.548625 | K2: 0.148021 | L2: 1.088325 | M2: 0.00414 | N2: 1.410868 | O2: 2.095849 | P2: 1.583708 | Q2: 8.220691 | R2: 0.181031 | S2: 0.146841 | T2: 1.088325
B3: Joby S4 | C3: 0.003135 | D3: 0.876388 | E3: 1.79714 | F3: 0.528918 | G3: 2.920245 | H3: 25.768693 | I3: 1.042898 | J3: 0.528918 | K3: 0.06635 | L3: 0.676034 | M3: 0.003135 | N3: 0.876388 | O3: 1.79714 | P3: 1.250689 | Q3: 5.172211 | R3: 0.126243 | S3: 0.065456 | T3: 0.676034
B4: Supernal S-A2 | C4: 0.004368 | D4: 1.040426 | E4: 2.277308 | F4: 0.648287 | G4: 3.964715 | H4: 45.7638 | I4: 1.348611 | J4: 0.648287 | K4: 0.138648 | L4: 0.802571 | M4: 0.004368 | N4: 1.040426 | O4: 2.277308 | P4: 1.725403 | Q4: 9.185566 | R4: 0.179584 | S4: 0.137403 | T4: 0.802571
A6: 45 miles | B6: Archer Midnight | C6: 0.00414 | D6: 1.410868 | E6: 2.095849 | F6: 0.548625 | G6: 3.448231 | H6: 67.380308 | I6: 0.968789 | J6: 0.548625 | K6: 0.148021 | L6: 1.088325 | M6: 0.00414 | N6: 1.410868 | O6: 2.095849 | P6: 1.583708 | Q6: 8.220691 | R6: 0.181031 | S6: 0.146841 | T6: 1.088325
B7: Joby S4 | C7: 0.003135 | D7: 0.876388 | E7: 1.79714 | F7: 0.528918 | G7: 2.920245 | H7: 42.393657 | I7: 1.042898 | J7: 0.528918 | K7: 0.06635 | L7: 0.676034 | M7: 0.003135 | N7: 0.876388 | O7: 1.79714 | P7: 1.250689 | Q7: 5.172211 | R7: 0.126243 | S7: 0.065456 | T7: 0.676034
B8: Supernal S-A2 | C8: 0.004368 | D8: 1.040426 | E8: 2.277308 | F8: 0.648287 | G8: 3.964715 | H8: 75.288832 | I8: 1.348611 | J8: 0.648287 | K8: 0.138648 | L8: 0.802571 | M8: 0.004368 | N8: 1.040426 | O8: 2.277308 | P8: 1.725403 | Q8: 9.185566 | R8: 0.179584 | S8: 0.137403 | T8: 0.802571
A10: 60 miles | B10: Archer Midnight | C10: 0.00414 | D10: 1.410868 | E10: 2.095849 | F10: 0.548625 | G10: 3.448231 | H10: 93.803958 | I10: 0.968789 | J10: 0.548625 | K10: 0.148021 | L10: 1.088325 | M10: 0.00414 | N10: 1.410868 | O10: 2.095849 | P10: 1.583708 | Q10: 8.220691 | R10: 0.181031 | S10: 0.146841 | T10: 1.088325
B11: Joby S4 | C11: 0.003135 | D11: 0.876388 | E11: 1.79714 | F11: 0.528918 | G11: 2.920245 | H11: 59.01862 | I11: 1.042898 | J11: 0.528918 | K11: 0.06635 | L11: 0.676034 | M11: 0.003135 | N11: 0.876388 | O11: 1.79714 | P11: 1.250689 | Q11: 5.172211 | R11: 0.126243 | S11: 0.065456 | T11: 0.676034
B12: Supernal S-A2 | C12: 0.004368 | D12: 1.040426 | E12: 2.277308 | F12: 0.648287 | G12: 3.964715 | H12: 104.81386 | I12: 1.348611 | J12: 0.648287 | K12: 0.138648 | L12: 0.802571 | M12: 0.004368 | N12: 1.040426 | O12: 2.277308 | P12: 1.725403 | Q12: 9.185566 | R12: 0.179584 | S12: 0.137403 | T12: 0.802571
A15: 30 miles | C15: Total energy
B16: Archer Midnight | C16: =SUM(C2:T2) -> 65.949584
B17: Joby S4 | C17: =SUM(C3:T3) -> 44.176015
B18: Supernal S-A2 | C18: =SUM(C4:T4) -> 71.98965
C21: Total energy
A22: 45 miles | B22: Archer Midnight | C22: =SUM(C6:T6) -> 92.373234
B23: Joby S4 | C23: =SUM(C7:T7) -> 60.800979
B24: Supernal S-A2 | C24: =SUM(C8:T8) -> 101.51468
C27: Total energy
A28: 60 miles | B28: Archer Midnight | C28: =SUM(C10:T10) -> 118.79688
B29: Joby S4 | C29: =SUM(C11:T11) -> 77.425942
B30: Supernal S-A2 | C30: =SUM(C12:T12) -> 131.03971
T39: TOTAL
U40: Archer Midnight | V40: Joby S4 | W40: Supernal S-A2
T41: Depart Taxi | U41: =C2 -> 0.00414 | V41: =C3 -> 0.003135 | W41: =C4 -> 0.004368
T42: Hover Climb | U42: =D2 -> 1.410868 | V42: =D3 -> 0.876388 | W42: =D4 -> 1.040426
T43: Transition Climb | U43: =E2 -> 2.095849 | V43: =E3 -> 1.79714 | W43: =E4 -> 2.277308
T44: Depart Procedures | U44: =F2 -> 0.548625 | V44: =F3 -> 0.528918 | W44: =F4 -> 0.648287
T45: Accelerate Climb | U45: =G2 -> 3.448231 | V45: =G3 -> 2.920245 | W45: =G4 -> 3.964715
T46: Cruise (30 mi) | U46: =H2 -> 40.956658 | V46: =H3 -> 25.768693 | W46: =H4 -> 45.7638
T47: Cruise (45 mi) | U47: =H6 -> 67.380308 | V47: =H7 -> 42.393657 | W47: =H8 -> 75.288832
T48: Cruise (60 mi) | U48: =H10 -> 93.803958 | V48: =H11 -> 59.01862 | W48: =H12 -> 104.81386
T49: Decelerate Descend | U49: =I2 -> 0.968789 | V49: =I3 -> 1.042898 | W49: =I4 -> 1.348611
T50: Arrive Procedures | U50: =J2 -> 0.548625 | V50: =J3 -> 0.528918 | W50: =J4 -> 0.648287
T51: Transition Descend | U51: =K2 -> 0.148021 | V51: =K3 -> 0.06635 | W51: =K4 -> 0.138648
T52: Hover Descend | U52: =L2 -> 1.088325 | V52: =L3 -> 0.676034 | W52: =L4 -> 0.802571
T53: Arrive Taxi | U53: =M2 -> 0.00414 | V53: =M3 -> 0.003135 | W53: =M4 -> 0.004368
T54: Reserve Hover Climb | U54: =N2 -> 1.410868 | V54: =N3 -> 0.876388 | W54: =N4 -> 1.040426
T55: Reserve Transition Climb | U55: =O2 -> 2.095849 | V55: =O3 -> 1.79714 | W55: =O4 -> 2.277308
T56: Reserve Accelerate Climb | U56: =P2 -> 1.583708 | V56: =P3 -> 1.250689 | W56: =P4 -> 1.725403
...

Sheet 3000 ft
C1: Depart Taxi | D1: Hover Climb | E1: Transition Climb | F1: Depart Procedures | G1: Accelerate Climb | H1: Cruise | I1: Decelerate Descend | J1: Arrive Procedures | K1: Transition Descend | L1: Hover Descend | M1: Arrive Taxi | N1: Reserve Hover Climb | O1: Reserve Transition Climb | P1: Reserve Accelerate Climb | Q1: Reserve Cruise | R1: Reserve Decelerate Descend | S1: Reserve Transition Descend | T1: Reserve Hover Descend
A2: 30 miles | B2: Archer Midnight | C2: 0.00414 | D2: 2.655278 | E2: 2.819013 | F2: 0.548909 | G2: 5.65707 | H2: 30.361973 | I2: 3.170643 | J2: 0.548909 | K2: 0.073526 | L2: 2.33266 | M2: 0.00414 | N2: 2.655278 | O2: 2.819013 | P2: 1.953182 | Q2: 5.813995 | R2: 0.104002 | S2: 0.079146 | T2: 2.33266
B3: Joby S4 | C3: 0.003135 | D3: 1.649377 | E3: 2.55495 | F3: 0.529222 | G3: 4.903259 | H3: 19.434765 | I3: 3.020624 | J3: 0.529222 | K3: 0.476162 | L3: 1.448976 | M3: 0.003135 | N3: 1.649377 | O3: 2.55495 | P3: 1.582202 | Q3: 3.721551 | R3: 0.057049 | S3: 0.480418 | T3: 1.448976
B4: Supernal S-A2 | C4: 0.004368 | D4: 1.958099 | E4: 3.106308 | F4: 0.648757 | G4: 6.62402 | H4: 33.958109 | I4: 4.000546 | J4: 0.648757 | K4: 0.209495 | L4: 1.720189 | M4: 0.004368 | N4: 1.958099 | O4: 3.106308 | P4: 2.170028 | Q4: 6.502617 | R4: 0.086804 | S4: 0.215425 | T4: 1.720189
A6: 45 miles | B6: Archer Midnight | C6: 0.00414 | D6: 2.655278 | E6: 2.819013 | F6: 0.548909 | G6: 5.65707 | H6: 56.201949 | I6: 3.170643 | J6: 0.548909 | K6: 0.073526 | L6: 2.33266 | M6: 0.00414 | N6: 2.655278 | O6: 2.819013 | P6: 1.953182 | Q6: 5.813995 | R6: 0.104002 | S6: 0.079146 | T6: 2.33266
B7: Joby S4 | C7: 0.003135 | D7: 1.649377 | E7: 2.55495 | F7: 0.529222 | G7: 4.903259 | H7: 35.974991 | I7: 3.020624 | J7: 0.529222 | K7: 0.476162 | L7: 1.448976 | M7: 0.003135 | N7: 1.649377 | O7: 2.55495 | P7: 1.582202 | Q7: 3.721551 | R7: 0.057049 | S7: 0.480418 | T7: 1.448976
B8: Supernal S-A2 | C8: 0.004368 | D8: 1.958099 | E8: 3.106308 | F8: 0.648757 | G8: 6.62402 | H8: 62.858627 | I8: 4.000546 | J8: 0.648757 | K8: 0.209495 | L8: 1.720189 | M8: 0.004368 | N8: 1.958099 | O8: 3.106308 | P8: 2.170028 | Q8: 6.502617 | R8: 0.086804 | S8: 0.215425 | T8: 1.720189
A10: 60 miles | B10: Archer Midnight | C10: 0.00414 | D10: 2.655278 | E10: 2.819013 | F10: 0.548909 | G10: 5.65707 | H10: 82.041926 | I10: 3.170643 | J10: 0.548909 | K10: 0.073526 | L10: 2.33266 | M10: 0.00414 | N10: 2.655278 | O10: 2.819013 | P10: 1.953182 | Q10: 5.813995 | R10: 0.104002 | S10: 0.079146 | T10: 2.33266
B11: Joby S4 | C11: 0.003135 | D11: 1.649377 | E11: 2.55495 | F11: 0.529222 | G11: 4.903259 | H11: 52.515216 | I11: 3.020624 | J11: 0.529222 | K11: 0.476162 | L11: 1.448976 | M11: 0.003135 | N11: 1.649377 | O11: 2.55495 | P11: 1.582202 | Q11: 3.721551 | R11: 0.057049 | S11: 0.480418 | T11: 1.448976
B12: Supernal S-A2 | C12: 0.004368 | D12: 1.958099 | E12: 3.106308 | F12: 0.648757 | G12: 6.62402 | H12: 91.759145 | I12: 4.000546 | J12: 0.648757 | K12: 0.209495 | L12: 1.720189 | M12: 0.004368 | N12: 1.958099 | O12: 3.106308 | P12: 2.170028 | Q12: 6.502617 | R12: 0.086804 | S12: 0.215425 | T12: 1.720189
A15: 30 miles | C15: Total energy
B16: Archer Midnight | C16: =SUM(C2:T2) -> 63.933537
B17: Joby S4 | C17: =SUM(C3:T3) -> 46.04735
B18: Supernal S-A2 | C18: =SUM(C4:T4) -> 68.642486
C21: Total energy
A22: 45 miles | B22: Archer Midnight | C22: =SUM(C6:T6) -> 89.773513
B23: Joby S4 | C23: =SUM(C7:T7) -> 62.587576
B24: Supernal S-A2 | C24: =SUM(C8:T8) -> 97.543004
C27: Total energy
A28: 60 miles | B28: Archer Midnight | C28: =SUM(C10:T10) -> 115.61349
B29: Joby S4 | C29: =SUM(C11:T11) -> 79.127801
B30: Supernal S-A2 | C30: =SUM(C12:T12) -> 126.44352
T39: TOTAL
U40: Archer Midnight | V40: Joby S4 | W40: Supernal S-A2
T41: Depart Taxi | U41: =C2 -> 0.00414 | V41: =C3 -> 0.003135 | W41: =C4 -> 0.004368
T42: Hover Climb | U42: =D2 -> 2.655278 | V42: =D3 -> 1.649377 | W42: =D4 -> 1.958099
T43: Transition Climb | U43: =E2 -> 2.819013 | V43: =E3 -> 2.55495 | W43: =E4 -> 3.106308
T44: Depart Procedures | U44: =F2 -> 0.548909 | V44: =F3 -> 0.529222 | W44: =F4 -> 0.648757
T45: Accelerate Climb | U45: =G2 -> 5.65707 | V45: =G3 -> 4.903259 | W45: =G4 -> 6.62402
T46: Cruise (30 mi) | U46: =H2 -> 30.361973 | V46: =H3 -> 19.434765 | W46: =H4 -> 33.958109
T47: Cruise (45 mi) | U47: =H6 -> 56.201949 | V47: =H7 -> 35.974991 | W47: =H8 -> 62.858627
T48: Cruise (60 mi) | U48: =H10 -> 82.041926 | V48: =H11 -> 52.515216 | W48: =H12 -> 91.759145
T49: Decelerate Descend | U49: =I2 -> 3.170643 | V49: =I3 -> 3.020624 | W49: =I4 -> 4.000546
T50: Arrive Procedures | U50: =J2 -> 0.548909 | V50: =J3 -> 0.529222 | W50: =J4 -> 0.648757
T51: Transition Descend | U51: =K2 -> 0.073526 | V51: =K3 -> 0.476162 | W51: =K4 -> 0.209495
T52: Hover Descend | U52: =L2 -> 2.33266 | V52: =L3 -> 1.448976 | W52: =L4 -> 1.720189
T53: Arrive Taxi | U53: =M2 -> 0.00414 | V53: =M3 -> 0.003135 | W53: =M4 -> 0.004368
T54: Reserve Hover Climb | U54: =N2 -> 2.655278 | V54: =N3 -> 1.649377 | W54: =N4 -> 1.958099
T55: Reserve Transition Climb | U55: =O2 -> 2.819013 | V55: =O3 -> 2.55495 | W55: =O4 -> 3.106308
T56: Reserve Accelerate Climb | U56: =P2 -> 1.953182 | V56: =P3 -> 1.582202 | W56: =P4 -> 2.170028
...

Sheet All
C1: Total energy | E1: % Drop
A2: 30 miles | C2: 1500 ft | D2: 3000 ft
B3: Archer Midnight | C3: ='1500 ft'!C16 -> 65.949584 | D3: ='3000 ft'!C16 -> 63.933537 | E3: =1-D3/C3 -> 0.030569518
B4: Joby S4 | C4: ='1500 ft'!C17 -> 44.176015 | D4: ='3000 ft'!C17 -> 46.04735 | E4: =1-D4/C4 -> -0.042360883
B5: Supernal S-A2 | C5: ='1500 ft'!C18 -> 71.98965 | D5: ='3000 ft'!C18 -> 68.642486 | E5: =1-D5/C5 -> 0.046495073
A7: 45 miles | B7: Archer Midnight | C7: ='1500 ft'!C22 -> 92.373234 | D7: ='3000 ft'!C22 -> 89.773513 | E7: =1-D7/C7 -> 0.028143661
B8: Joby S4 | C8: ='1500 ft'!C23 -> 60.800979 | D8: ='3000 ft'!C23 -> 62.587576 | E8: =1-D8/C8 -> -0.029384346
B9: Supernal S-A2 | C9: ='1500 ft'!C24 -> 101.51468 | D9: ='3000 ft'!C24 -> 97.543004 | E9: =1-D9/C9 -> 0.039124173
A11: 60 miles | B11: Archer Midnight | C11: ='1500 ft'!C28 -> 118.79688 | D11: ='3000 ft'!C28 -> 115.61349 | E11: =1-D11/C11 -> 0.026796949
B12: Joby S4 | C12: ='1500 ft'!C29 -> 77.425942 | D12: ='3000 ft'!C29 -> 79.127801 | E12: =1-D12/C12 -> -0.021980475
B13: Supernal S-A2 | C13: ='1500 ft'!C30 -> 131.03971 | D13: ='3000 ft'!C30 -> 126.44352 | E13: =1-D13/C13 -> 0.035074802
B17: TOTAL
B18: Mission Profile | C18: Archer Midnight | F18: Joby S4 | I18: Supernal S-A2
C19: 1500 ft | D19: 3000 ft | E19: % Drop | F19: 1500 ft | G19: 3000 ft | H19: % Drop | I19: 1500 ft | J19: 3000 ft | K19: % Drop
B20: Depart Taxi | C20: ='1500 ft'!U41 -> 0.00414 | D20: {='3000 ft'!U41:U60} -> 0.00414 | E20: =1-C20/D20 -> 0 | F20: {='1500 ft'!V41:V60} -> 0.003135 | G20: {='3000 ft'!V41:V60} -> 0.003135 | H20: =1-F20/G20 -> 0 | I20: {='1500 ft'!W41:W60} -> 0.004368 | J20: {='3000 ft'!W41:W60} -> 0.004368 | K20: =1-I20/J20 -> 0
B21: Hover Climb | C21: ='1500 ft'!U42 -> 1.410868 | D21: 2.655278 | E21: =1-C21/D21 -> 0.46865526 | F21: 0.876388 | G21: 1.649377 | H21: =1-F21/G21 -> 0.46865513 | I21: 1.040426 | J21: 1.958099 | K21: =1-I21/J21 -> 0.46865506
B22: Transition Climb | C22: ='1500 ft'!U43 -> 2.095849 | D22: 2.819013 | E22: =1-C22/D22 -> 0.25653092 | F22: 1.79714 | G22: 2.55495 | H22: =1-F22/G22 -> 0.29660463 | I22: 2.277308 | J22: 3.106308 | K22: =1-I22/J22 -> 0.2668763
B23: Depart Procedures | C23: ='1500 ft'!U44 -> 0.548625 | D23: 0.548909 | E23: =1-C23/D23 -> 0.00051738995 | F23: 0.528918 | G23: 0.529222 | H23: =1-F23/G23 -> 0.00057442812 | I23: 0.648287 | J23: 0.648757 | K23: =1-I23/J23 -> 0.00072446232
B24: Accelerate Climb | C24: ='1500 ft'!U45 -> 3.448231 | D24: 5.65707 | E24: =1-C24/D24 -> 0.39045637 | F24: 2.920245 | G24: 4.903259 | H24: =1-F24/G24 -> 0.40442775 | I24: 3.964715 | J24: 6.62402 | K24: =1-I24/J24 -> 0.40146391
B25: Cruise (30 mi) | C25: ='1500 ft'!U46 -> 40.956658 | D25: 30.361973 | E25: =1-C25/D25 -> -0.34894587 | F25: 25.768693 | G25: 19.434765 | H25: =1-F25/G25 -> -0.32590711 | I25: 45.7638 | J25: 33.958109 | K25: =1-I25/J25 -> -0.34765455
B26: Cruise (45 mi) | C26: ='1500 ft'!U47 -> 67.380308 | D26: 56.201949 | E26: =1-C26/D26 -> -0.19889629 | F26: 42.393657 | G26: 35.974991 | H26: =1-F26/G26 -> -0.17842023 | I26: 75.288832 | J26: 62.858627 | K26: =1-I26/J26 -> -0.19774859
B27: Cruise (60 mi) | C27: ='1500 ft'!U48 -> 93.803958 | D27: 82.041926 | E27: =1-C27/D27 -> -0.14336611 | F27: 59.01862 | G27: 52.515216 | H27: =1-F27/G27 -> -0.12383847 | I27: 104.81386 | J27: 91.759145 | K27: =1-I27/J27 -> -0.14227159
B28: Decelerate Descend | C28: ='1500 ft'!U49 -> 0.968789 | D28: 3.170643 | E28: =1-C28/D28 -> 0.69445031 | F28: 1.042898 | G28: 3.020624 | H28: =1-F28/G28 -> 0.65474087 | I28: 1.348611 | J28: 4.000546 | K28: =1-I28/J28 -> 0.66289327
B29: Arrive Procedures | C29: ='1500 ft'!U50 -> 0.548625 | D29: 0.548909 | E29: =1-C29/D29 -> 0.00051738995 | F29: 0.528918 | G29: 0.529222 | H29: =1-F29/G29 -> 0.00057442812 | I29: 0.648287 | J29: 0.648757 | K29: =1-I29/J29 -> 0.00072446232
B30: Transition Descend | C30: ='1500 ft'!U51 -> 0.148021 | D30: 0.073526 | E30: =1-C30/D30 -> -1.013179 | F30: 0.06635 | G30: 0.476162 | H30: =1-F30/G30 -> 0.86065667 | I30: 0.138648 | J30: 0.209495 | K30: =1-I30/J30 -> 0.33817991
B31: Hover Descend | C31: ='1500 ft'!U52 -> 1.088325 | D31: 2.33266 | E31: =1-C31/D31 -> 0.53344036 | F31: 0.676034 | G31: 1.448976 | H31: =1-F31/G31 -> 0.53344017 | I31: 0.802571 | J31: 1.720189 | K31: =1-I31/J31 -> 0.53344022
B32: Arrive Taxi | C32: ='1500 ft'!U53 -> 0.00414 | D32: 0.00414 | E32: =1-C32/D32 -> 0 | F32: 0.003135 | G32: 0.003135 | H32: =1-F32/G32 -> 0 | I32: 0.004368 | J32: 0.004368 | K32: =1-I32/J32 -> 0
... B39: Reserve Hover Descend | C39: ='1500 ft'!U60 -> 1.088325 | D39: 2.33266 | E39: =1-C39/D39 -> 0.53344036 | F39: 0.676034 | G39: 1.448976 | H39: =1-F39/G39 -> 0.53344017 | I39: 0.802571 | J39: 1.720189 | K39: =1-I39/J39 -> 0.53344022
