Workbook

Sheet 1500 ft
C1: Depart Taxi | D1: Hover Climb | E1: Transition Climb | F1: Depart Procedures | G1: Accelerate Climb | H1: Cruise | I1: Decelerate Descend | J1: Arrive Procedures | K1: Transition Descend | L1: Hover Descend | M1: Arrive Taxi | N1: Reserve Hover Climb | O1: Reserve Transition Climb | P1: Reserve Accelerate Climb | Q1: Reserve Cruise | R1: Reserve Decelerate Descend | S1: Reserve Transition Descend | T1: Reserve Hover Descend
A2: 30 miles | B2: Archer Midnight | C2: 0.00414 | D2: 0.187235 | E2: 2.104751 | F2: 0.55039 | G2: 3.460097 | H2: 41.341488 | I2: 0.980656 | J2: 0.55039 | K2: 0.1567 | L2: 0.157483 | M2: 0.00414 | N2: 0.187235 | O2: 2.104751 | P2: 1.585685 | Q2: 8.297933 | R2: 0.180616 | S2: 0.155519 | T2: 0.157483
B3: Joby S4 | C3: 0.003135 | D3: 0.141768 | E3: 1.805163 | F3: 0.530053 | G3: 2.927872 | H3: 26.022308 | I3: 1.050524 | J3: 0.530053 | K3: 0.074229 | L3: 0.119241 | M3: 0.003135 | N3: 0.141768 | O3: 1.805163 | P3: 1.25196 | Q3: 5.223116 | R3: 0.125976 | S3: 0.073335 | T3: 0.119241
B4: Supernal S-A2 | C4: 0.004173 | D4: 0.188709 | E4: 2.153167 | F4: 0.603786 | G4: 3.756457 | H4: 41.05615 | I4: 1.257493 | J4: 0.603786 | K4: 0.151246 | L4: 0.158723 | M4: 0.004173 | N4: 0.188709 | O4: 2.153167 | P4: 1.643024 | Q4: 8.240661 | R4: 0.172619 | S4: 0.150057 | T4: 0.158723
A6: 45 miles | B6: Archer Midnight | C6: 0.00414 | D6: 0.187235 | E6: 2.104751 | F6: 0.55039 | G6: 3.460097 | H6: 68.013416 | I6: 0.980656 | J6: 0.55039 | K6: 0.1567 | L6: 0.157483 | M6: 0.00414 | N6: 0.187235 | O6: 2.104751 | P6: 1.585685 | Q6: 8.297933 | R6: 0.180616 | S6: 0.155519 | T6: 0.157483
B7: Joby S4 | C7: 0.003135 | D7: 0.141768 | E7: 1.805163 | F7: 0.530053 | G7: 2.927872 | H7: 42.810893 | I7: 1.050524 | J7: 0.530053 | K7: 0.074229 | L7: 0.119241 | M7: 0.003135 | N7: 0.141768 | O7: 1.805163 | P7: 1.25196 | Q7: 5.223116 | R7: 0.125976 | S7: 0.073335 | T7: 0.119241
B8: Supernal S-A2 | C8: 0.004173 | D8: 0.188709 | E8: 2.153167 | F8: 0.603786 | G8: 3.756457 | H8: 67.543989 | I8: 1.257493 | J8: 0.603786 | K8: 0.151246 | L8: 0.158723 | M8: 0.004173 | N8: 0.188709 | O8: 2.153167 | P8: 1.643024 | Q8: 8.240661 | R8: 0.172619 | S8: 0.150057 | T8: 0.158723
A10: 60 miles | B10: Archer Midnight | C10: 0.00414 | D10: 0.187235 | E10: 2.104751 | F10: 0.55039 | G10: 3.460097 | H10: 94.685344 | I10: 0.980656 | J10: 0.55039 | K10: 0.1567 | L10: 0.157483 | M10: 0.00414 | N10: 0.187235 | O10: 2.104751 | P10: 1.585685 | Q10: 8.297933 | R10: 0.180616 | S10: 0.155519 | T10: 0.157483
B11: Joby S4 | C11: 0.003135 | D11: 0.141768 | E11: 1.805163 | F11: 0.530053 | G11: 2.927872 | H11: 59.599479 | I11: 1.050524 | J11: 0.530053 | K11: 0.074229 | L11: 0.119241 | M11: 0.003135 | N11: 0.141768 | O11: 1.805163 | P11: 1.25196 | Q11: 5.223116 | R11: 0.125976 | S11: 0.073335 | T11: 0.119241
B12: Supernal S-A2 | C12: 0.004173 | D12: 0.188709 | E12: 2.153167 | F12: 0.603786 | G12: 3.756457 | H12: 94.031828 | I12: 1.257493 | J12: 0.603786 | K12: 0.151246 | L12: 0.158723 | M12: 0.004173 | N12: 0.188709 | O12: 2.153167 | P12: 1.643024 | Q12: 8.240661 | R12: 0.172619 | S12: 0.150057 | T12: 0.158723
A15: 30 miles | C15: Total energy
B16: Archer Midnight | C16: =SUM(C2:T2) -> 62.166692
B17: Joby S4 | C17: =SUM(C3:T3) -> 41.94804
B18: Supernal S-A2 | C18: =SUM(C4:T4) -> 62.644823
C21: Total energy
A22: 45 miles | B22: Archer Midnight | C22: =SUM(C6:T6) -> 88.83862
B23: Joby S4 | C23: =SUM(C7:T7) -> 58.736625
B24: Supernal S-A2 | C24: =SUM(C8:T8) -> 89.132662
C27: Total energy
A28: 60 miles | B28: Archer Midnight | C28: =SUM(C10:T10) -> 115.51055
B29: Joby S4 | C29: =SUM(C11:T11) -> 75.525211
B30: Supernal S-A2 | C30: =SUM(C12:T12) -> 115.6205
T39: TOTAL
U40: Archer Midnight | V40: Joby S4 | W40: Supernal S-A2
T41: Depart Taxi | U41: =C2 -> 0.00414 | V41: =C3 -> 0.003135 | W41: =C4 -> 0.004173
T42: Hover Climb | U42: =D2 -> 0.187235 | V42: =D3 -> 0.141768 | W42: =D4 -> 0.188709
T43: Transition Climb | U43: =E2 -> 2.104751 | V43: =E3 -> 1.805163 | W43: =E4 -> 2.153167
T44: Depart Procedures | U44: =F2 -> 0.55039 | V44: =F3 -> 0.530053 | W44: =F4 -> 0.603786
T45: Accelerate Climb | U45: =G2 -> 3.460097 | V45: =G3 -> 2.927872 | W45: =G4 -> 3.756457
T46: Cruise (30 mi) | U46: =H2 -> 41.341488 | V46: =H3 -> 26.022308 | W46: =H4 -> 41.05615
T47: Cruise (45 mi) | U47: =H6 -> 68.013416 | V47: =H7 -> 42.810893 | W47: =H8 -> 67.543989
T48: Cruise (60 mi) | U48: =H10 -> 94.685344 | V48: =H11 -> 59.599479 | W48: =H12 -> 94.031828
T49: Decelerate Descend | U49: =I2 -> 0.980656 | V49: =I3 -> 1.050524 | W49: =I4 -> 1.257493
T50: Arrive Procedures | U50: =J2 -> 0.55039 | V50: =J3 -> 0.530053 | W50: =J4 -> 0.603786
T51: Transition Descend | U51: =K2 -> 0.1567 | V51: =K3 -> 0.074229 | W51: =K4 -> 0.151246
T52: Hover Descend | U52: =L2 -> 0.157483 | V52: =L3 -> 0.119241 | W52: =L4 -> 0.158723
T53: Arrive Taxi | U53: =M2 -> 0.00414 | V53: =M3 -> 0.003135 | W53: =M4 -> 0.004173
T54: Reserve Hover Climb | U54: =N2 -> 0.187235 | V54: =N3 -> 0.141768 | W54: =N4 -> 0.188709
T55: Reserve Transition Climb | U55: =O2 -> 2.104751 | V55: =O3 -> 1.805163 | W55: =O4 -> 2.153167
T56: Reserve Accelerate Climb | U56: =P2 -> 1.585685 | V56: =P3 -> 1.25196 | W56: =P4 -> 1.643024
...

Sheet 3000 ft
C1: Depart Taxi | D1: Hover Climb | E1: Transition Climb | F1: Depart Procedures | G1: Accelerate Climb | H1: Cruise | I1: Decelerate Descend | J1: Arrive Procedures | K1: Transition Descend | L1: Hover Descend | M1: Arrive Taxi | N1: Reserve Hover Climb | O1: Reserve Transition Climb | P1: Reserve Accelerate Climb | Q1: Reserve Cruise | R1: Reserve Decelerate Descend | S1: Reserve Transition Descend | T1: Reserve Hover Descend
A2: 30 miles | B2: Archer Midnight | C2: 0.00414 | D2: 0.359594 | E2: 2.837276 | F2: 0.552865 | G2: 5.71025 | H2: 30.978339 | I2: 3.223824 | J2: 0.552865 | K2: 0.091789 | L2: 0.329842 | M2: 0.00414 | N2: 0.359594 | O2: 2.837276 | P2: 1.962046 | Q2: 5.932022 | R2: 0.102141 | S2: 0.097409 | T2: 0.329842
B3: Joby S4 | C3: 0.003135 | D3: 0.272272 | E3: 2.571291 | F3: 0.531767 | G3: 4.937473 | H3: 19.841049 | I3: 3.054837 | J3: 0.531767 | K3: 0.492503 | L3: 0.249745 | M3: 0.003135 | N3: 0.272272 | O3: 2.571291 | P3: 1.587904 | Q3: 3.79935 | R3: 0.055852 | S3: 0.496759 | T3: 0.249745
B4: Supernal S-A2 | C4: 0.004173 | D4: 0.362425 | E4: 2.923309 | F4: 0.606305 | G4: 6.293784 | H4: 30.986 | I4: 3.78778 | J4: 0.606305 | K4: 0.156204 | L4: 0.332439 | M4: 0.004173 | N4: 0.362425 | O4: 2.923309 | P4: 2.067257 | Q4: 5.933489 | R4: 0.084095 | S4: 0.161869 | T4: 0.332439
A6: 45 miles | B6: Archer Midnight | C6: 0.00414 | D6: 0.359594 | E6: 2.837276 | F6: 0.552865 | G6: 5.71025 | H6: 57.342883 | I6: 3.223824 | J6: 0.552865 | K6: 0.091789 | L6: 0.329842 | M6: 0.00414 | N6: 0.359594 | O6: 2.837276 | P6: 1.962046 | Q6: 5.932022 | R6: 0.102141 | S6: 0.097409 | T6: 0.329842
B7: Joby S4 | C7: 0.003135 | D7: 0.272272 | E7: 2.571291 | F7: 0.531767 | G7: 4.937473 | H7: 36.727049 | I7: 3.054837 | J7: 0.531767 | K7: 0.492503 | L7: 0.249745 | M7: 0.003135 | N7: 0.272272 | O7: 2.571291 | P7: 1.587904 | Q7: 3.79935 | R7: 0.055852 | S7: 0.496759 | T7: 0.249745
B8: Supernal S-A2 | C8: 0.004173 | D8: 0.362425 | E8: 2.923309 | F8: 0.606305 | G8: 6.293784 | H8: 57.357064 | I8: 3.78778 | J8: 0.606305 | K8: 0.156204 | L8: 0.332439 | M8: 0.004173 | N8: 0.362425 | O8: 2.923309 | P8: 2.067257 | Q8: 5.933489 | R8: 0.084095 | S8: 0.161869 | T8: 0.332439
A10: 60 miles | B10: Archer Midnight | C10: 0.00414 | D10: 0.359594 | E10: 2.837276 | F10: 0.552865 | G10: 5.71025 | H10: 83.707427 | I10: 3.223824 | J10: 0.552865 | K10: 0.091789 | L10: 0.329842 | M10: 0.00414 | N10: 0.359594 | O10: 2.837276 | P10: 1.962046 | Q10: 5.932022 | R10: 0.102141 | S10: 0.097409 | T10: 0.329842
B11: Joby S4 | C11: 0.003135 | D11: 0.272272 | E11: 2.571291 | F11: 0.531767 | G11: 4.937473 | H11: 53.613048 | I11: 3.054837 | J11: 0.531767 | K11: 0.492503 | L11: 0.249745 | M11: 0.003135 | N11: 0.272272 | O11: 2.571291 | P11: 1.587904 | Q11: 3.79935 | R11: 0.055852 | S11: 0.496759 | T11: 0.249745
B12: Supernal S-A2 | C12: 0.004173 | D12: 0.362425 | E12: 2.923309 | F12: 0.606305 | G12: 6.293784 | H12: 83.728128 | I12: 3.78778 | J12: 0.606305 | K12: 0.156204 | L12: 0.332439 | M12: 0.004173 | N12: 0.362425 | O12: 2.923309 | P12: 2.067257 | Q12: 5.933489 | R12: 0.084095 | S12: 0.161869 | T12: 0.332439
A15: 30 miles | C15: Total energy
B16: Archer Midnight | C16: =SUM(C2:T2) -> 56.265254
B17: Joby S4 | C17: =SUM(C3:T3) -> 41.522147
B18: Supernal S-A2 | C18: =SUM(C4:T4) -> 57.92778
C21: Total energy
A22: 45 miles | B22: Archer Midnight | C22: =SUM(C6:T6) -> 82.629798
B23: Joby S4 | C23: =SUM(C7:T7) -> 58.408147
B24: Supernal S-A2 | C24: =SUM(C8:T8) -> 84.298844
C27: Total energy
A28: 60 miles | B28: Archer Midnight | C28: =SUM(C10:T10) -> 108.99434
B29: Joby S4 | C29: =SUM(C11:T11) -> 75.294146
B30: Supernal S-A2 | C30: =SUM(C12:T12) -> 110.66991
T39: TOTAL
U40: Archer Midnight | V40: Joby S4 | W40: Supernal S-A2
T41: Depart Taxi | U41: =C2 -> 0.00414 | V41: =C3 -> 0.003135 | W41: =C4 -> 0.004173
T42: Hover Climb | U42: =D2 -> 0.359594 | V42: =D3 -> 0.272272 | W42: =D4 -> 0.362425
T43: Transition Climb | U43: =E2 -> 2.837276 | V43: =E3 -> 2.571291 | W43: =E4 -> 2.923309
T44: Depart Procedures | U44: =F2 -> 0.552865 | V44: =F3 -> 0.531767 | W44: =F4 -> 0.606305
T45: Accelerate Climb | U45: =G2 -> 5.71025 | V45: =G3 -> 4.937473 | W45: =G4 -> 6.293784
T46: Cruise (30 mi) | U46: =H2 -> 30.978339 | V46: =H3 -> 19.841049 | W46: =H4 -> 30.986
T47: Cruise (45 mi) | U47: =H6 -> 57.342883 | V47: =H7 -> 36.727049 | W47: =H8 -> 57.357064
T48: Cruise (60 mi) | U48: =H10 -> 83.707427 | V48: =H11 -> 53.613048 | W48: =H12 -> 83.728128
T49: Decelerate Descend | U49: =I2 -> 3.223824 | V49: =I3 -> 3.054837 | W49: =I4 -> 3.78778
T50: Arrive Procedures | U50: =J2 -> 0.552865 | V50: =J3 -> 0.531767 | W50: =J4 -> 0.606305
T51: Transition Descend | U51: =K2 -> 0.091789 | V51: =K3 -> 0.492503 | W51: =K4 -> 0.156204
T52: Hover Descend | U52: =L2 -> 0.329842 | V52: =L3 -> 0.249745 | W52: =L4 -> 0.332439
T53: Arrive Taxi | U53: =M2 -> 0.00414 | V53: =M3 -> 0.003135 | W53: =M4 -> 0.004173
T54: Reserve Hover Climb | U54: =N2 -> 0.359594 | V54: =N3 -> 0.272272 | W54: =N4 -> 0.362425
T55: Reserve Transition Climb | U55: =O2 -> 2.837276 | V55: =O3 -> 2.571291 | W55: =O4 -> 2.923309
T56: Reserve Accelerate Climb | U56: =P2 -> 1.962046 | V56: =P3 -> 1.587904 | W56: =P4 -> 2.067257
...

Sheet All
C1: Total energy | E1: % Drop
A2: 30 miles | C2: 1500 ft | D2: 3000 ft
B3: Archer Midnight | C3: ='1500 ft'!C16 -> 62.166692 | D3: ='3000 ft'!C16 -> 56.265254 | E3: =1-D3/C3 -> 0.094929259
B4: Joby S4 | C4: ='1500 ft'!C17 -> 41.94804 | D4: ='3000 ft'!C17 -> 41.522147 | E4: =1-D4/C4 -> 0.01015287
B5: Supernal S-A2 | C5: ='1500 ft'!C18 -> 62.644823 | D5: ='3000 ft'!C18 -> 57.92778 | E5: =1-D5/C5 -> 0.075298209
A7: 45 miles | B7: Archer Midnight | C7: ='1500 ft'!C22 -> 88.83862 | D7: ='3000 ft'!C22 -> 82.629798 | E7: =1-D7/C7 -> 0.069888771
B8: Joby S4 | C8: ='1500 ft'!C23 -> 58.736625 | D8: ='3000 ft'!C23 -> 58.408147 | E8: =1-D8/C8 -> 0.0055923881
B9: Supernal S-A2 | C9: ='1500 ft'!C24 -> 89.132662 | D9: ='3000 ft'!C24 -> 84.298844 | E9: =1-D9/C9 -> 0.054231725
A11: 60 miles | B11: Archer Midnight | C11: ='1500 ft'!C28 -> 115.51055 | D11: ='3000 ft'!C28 -> 108.99434 | E11: =1-D11/C11 -> 0.056412216
B12: Joby S4 | C12: ='1500 ft'!C29 -> 75.525211 | D12: ='3000 ft'!C29 -> 75.294146 | E12: =1-D12/C12 -> 0.003059442
B13: Supernal S-A2 | C13: ='1500 ft'!C30 -> 115.6205 | D13: ='3000 ft'!C30 -> 110.66991 | E13: =1-D13/C13 -> 0.042817606
